Что вы думаете? Выполнится ли .catch? Поясните свой ответ.

new Promise(function(resolve, reject) {
  setTimeout(() => {
    throw new Error("Whoops!");
  }, 1000);
}).catch(alert);

Ответ: да, Выполнится. catch отловит исключение, брошенное промисом. -- нет, потому что catch не ловит отложенные ошибки